<?xml version="1.0" encoding="utf-8"?>
<!-- =================================================================================== -->
<!-- |    This document was autogenerated by xacro from full_cell.xacro                | -->
<!-- |    EDITING THIS FILE BY HAND IS NOT RECOMMENDED                                 | -->
<!-- =================================================================================== -->
<robot name="full_cell">
  <!-- Conversion were obtained from http://www.e-paint.co.uk/Lab_values.asp
       unless otherwise stated. -->
  <!-- =================================================================================== -->
  <link name="world"/>
  <joint name="A_world_joint" type="fixed">
    <parent link="world"/>
    <child link="A_axis"/>
    <origin rpy="0.0 0.0 0.0" xyz="0.0 0.0 0.0"/>
  </joint>
  <!-- Conversion were obtained from http://www.e-paint.co.uk/Lab_values.asp
       unless otherwise stated. -->
  <!-- Conversion were obtained from http://www.e-paint.co.uk/Lab_values.asp
       unless otherwise stated. -->
  <link name="A_axis">
    <inertial>
      <origin xyz="0.0 0.0 0.0"/>
      <mass value="120"/>
      <inertia ixx="-4.98000" ixy="-0.00000" ixz="2.70000" iyy="-5.95200" iyz="-0.00000" izz="0.82800"/>
    </inertial>
    <visual>
      <geometry>
        <mesh filename="package://princeton_cell/meshes/visual/axis.stl"/>
      </geometry>
      <material name="">
        <color rgba="0.9254902 0.9254902 0.9058824 1"/>
      </material>
    </visual>
    <collision>
      <geometry>
        <mesh filename="package://princeton_cell/meshes/collision/axis.stl"/>
      </geometry>
    </collision>
  </link>
  <joint name="A_cart_joint" type="prismatic">
    <parent link="A_axis"/>
    <child link="A_cart"/>
    <origin rpy="0 0 0 " xyz="0 0 0"/>
    <axis xyz="1 0 0"/>
    <limit effort="100000" lower="0.0" upper="4.0" velocity="2.618"/>
    <dynamics damping="0.2" friction="0"/>
  </joint>
  <link name="A_cart">
    <inertial>
      <origin xyz="0.0 0.0 0.0"/>
      <mass value="120.00000"/>
      <inertia ixx="-4.98000" ixy="-0.00000" ixz="2.70000" iyy="-5.95200" iyz="-0.00000" izz="0.82800"/>
    </inertial>
    <visual>
      <geometry>
        <mesh filename="package://princeton_cell/meshes/visual/cart.stl"/>
      </geometry>
      <material name="">
        <color rgba="0.9254902 0.9254902 0.9058824 1"/>
      </material>
    </visual>
    <collision>
      <geometry>
        <mesh filename="package://princeton_cell/meshes/collision/cart.stl"/>
      </geometry>
    </collision>
  </link>
  <joint name="A_abb_joint" type="fixed">
    <parent link="A_cart"/>
    <child link="A_base_link"/>
    <origin rpy="0 0 1.57079632679 " xyz="0 0 0 "/>
    <dynamics damping="0.2" friction="0"/>
  </joint>
  <!-- link list -->
  <link name="A_base_link">
    <inertial>
      <origin xyz="0.0 0.0 0.0"/>
      <mass value="120.00000"/>
      <inertia ixx="-4.98000" ixy="-0.00000" ixz="2.70000" iyy="-5.95200" iyz="-0.00000" izz="0.82800"/>
    </inertial>
    <visual>
      <geometry>
        <mesh filename="package://abb_irb4600_40_255/meshes/visual/base_link.stl"/>
      </geometry>
      <material name="">
        <color rgba="0.7725490 0.7803922 0.7686275 1"/>
      </material>
    </visual>
    <collision>
      <geometry>
        <mesh filename="package://abb_irb4600_40_255/meshes/collision/base_link.stl"/>
      </geometry>
    </collision>
  </link>
  <link name="A_link_1">
    <inertial>
      <origin xyz="0.18000 0.00000 0.50000"/>
      <mass value="120.00000"/>
      <inertia ixx="-4.98000" ixy="-0.00000" ixz="2.70000" iyy="-5.95200" iyz="-0.00000" izz="0.82800"/>
    </inertial>
    <visual>
      <geometry>
        <mesh filename="package://abb_irb4600_40_255/meshes/visual/link_1.stl"/>
      </geometry>
      <material name="">
        <color rgba="0.7725490 0.7803922 0.7686275 1"/>
      </material>
    </visual>
    <collision>
      <geometry>
        <mesh filename="package://abb_irb4600_40_255/meshes/collision/link_1.stl"/>
      </geometry>
    </collision>
  </link>
  <link name="A_link_2">
    <inertial>
      <origin xyz="0.94000 0.08000 -0.34000"/>
      <mass value="120.00000"/>
      <inertia ixx="-2.96000" ixy="2.25600" ixz="-9.58800" iyy="-18.72601" iyz="-0.81600" izz="-14.95000"/>
    </inertial>
    <visual>
      <geometry>
        <mesh filename="package://abb_irb4600_40_255/meshes/visual/link_2.stl"/>
      </geometry>
      <material name="">
        <color rgba="0.7725490 0.7803922 0.7686275 1"/>
      </material>
    </visual>
    <collision>
      <geometry>
        <mesh filename="package://abb_irb4600_40_255/meshes/collision/link_2.stl"/>
      </geometry>
    </collision>
  </link>
  <link name="A_link_3">
    <inertial>
      <origin xyz="0.07000 -0.26600 0.08800"/>
      <mass value="120.00000"/>
      <inertia ixx="1.34500" ixy="-0.55860" ixz="0.18480" iyy="4.65068" iyz="-0.70224" izz="2.76032"/>
    </inertial>
    <visual>
      <geometry>
        <mesh filename="package://abb_irb4600_40_255/meshes/visual/link_3.stl"/>
      </geometry>
      <material name="">
        <color rgba="0.7725490 0.7803922 0.7686275 1"/>
      </material>
    </visual>
    <collision>
      <geometry>
        <mesh filename="package://abb_irb4600_40_255/meshes/collision/link_3.stl"/>
      </geometry>
    </collision>
  </link>
  <link name="A_link_4">
    <inertial>
      <origin xyz="0.00000 0.00000 1.00000"/>
      <mass value="40.00000"/>
      <inertia ixx="-8.00000" ixy="-0.00000" ixz="-0.00000" iyy="-8.00000" iyz="-0.00000" izz="0.48200"/>
    </inertial>
    <visual>
      <geometry>
        <mesh filename="package://abb_irb4600_40_255/meshes/visual/link_4.stl"/>
      </geometry>
      <material name="">
        <color rgba="0.7725490 0.7803922 0.7686275 1"/>
      </material>
    </visual>
    <collision>
      <geometry>
        <mesh filename="package://abb_irb4600_40_255/meshes/collision/link_4.stl"/>
      </geometry>
    </collision>
  </link>
  <link name="A_link_5">
    <inertial>
      <origin xyz="0.14000 0.00000 0.00000"/>
      <mass value="10.00000"/>
      <inertia ixx="0.04000" ixy="-0.00000" ixz="-0.00000" iyy="-0.00900" iyz="-0.00000" izz="-0.00400"/>
    </inertial>
    <visual>
      <geometry>
        <mesh filename="package://abb_irb4600_40_255/meshes/visual/link_5.stl"/>
      </geometry>
      <material name="">
        <color rgba="0.7725490 0.7803922 0.7686275 1"/>
      </material>
    </visual>
    <collision>
      <geometry>
        <mesh filename="package://abb_irb4600_40_255/meshes/collision/link_5.stl"/>
      </geometry>
    </collision>
  </link>
  <link name="A_link_6">
    <inertial>
      <origin xyz="0.08100 -0.09100 0.33200"/>
      <mass value="5.00000"/>
      <inertia ixx="-0.29652" ixy="-0.03686" ixz="0.09396" iyy="-0.28792" iyz="-0.10556" izz="-0.04621"/>
    </inertial>
    <visual>
      <geometry>
        <mesh filename="package://abb_irb4600_40_255/meshes/visual/link_6.stl"/>
      </geometry>
      <material name="">
        <color rgba="0.1882353 0.1960784 0.2039216 1"/>
      </material>
    </visual>
    <collision>
      <geometry>
        <mesh filename="package://abb_irb4600_40_255/meshes/collision/link_6.stl"/>
      </geometry>
    </collision>
  </link>
  <link name="A_tool0"/>
  <!-- end of link list -->
  <!-- joint list -->
  <joint name="A_joint_1" type="revolute">
    <parent link="A_base_link"/>
    <child link="A_link_1"/>
    <origin rpy="0 0 0 " xyz="0 0 0"/>
    <axis xyz="0 0 1"/>
    <limit effort="100000" lower="-3.14159" upper="3.14159" velocity="2.618"/>
    <dynamics damping="0.2" friction="0"/>
  </joint>
  <joint name="A_joint_2" type="revolute">
    <parent link="A_link_1"/>
    <child link="A_link_2"/>
    <origin rpy="0 -0 0 " xyz="0.175 0 0.495"/>
    <axis xyz="0 1 0"/>
    <limit effort="100000" lower="-1.5708" upper="2.61799" velocity="2.618"/>
    <dynamics damping="0.2" friction="0"/>
  </joint>
  <joint name="A_joint_3" type="revolute">
    <parent link="A_link_2"/>
    <child link="A_link_3"/>
    <origin rpy="0 -0 0 " xyz="0 0 1.095"/>
    <axis xyz="0 1 0"/>
    <limit effort="100000" lower="-3.14159" upper="1.309" velocity="2.618"/>
    <dynamics damping="0.2" friction="0"/>
  </joint>
  <joint name="A_joint_4" type="revolute">
    <parent link="A_link_3"/>
    <child link="A_link_4"/>
    <origin rpy="0 -0 0 " xyz="0.332 0 0.175"/>
    <axis xyz="1 0 0"/>
    <limit effort="10000" lower="-6.98132" upper="6.98132" velocity="6.2832"/>
    <dynamics damping="0.2" friction="0"/>
  </joint>
  <joint name="A_joint_5" type="revolute">
    <parent link="A_link_4"/>
    <child link="A_link_5"/>
    <origin rpy="0 -0 0 " xyz="0.939 0 0"/>
    <axis xyz="0 1 0"/>
    <limit effort="100000" lower="-2.18166" upper="2.0944" velocity="6.2832"/>
    <dynamics damping="0.2" friction="0"/>
  </joint>
  <joint name="A_joint_6" type="revolute">
    <parent link="A_link_5"/>
    <child link="A_link_6"/>
    <origin rpy="0 1.57076 0 " xyz="0.135 0 0"/>
    <axis xyz="0 0 1"/>
    <limit effort="100000" lower="-6.98132" upper="6.98132" velocity="7.854"/>
    <dynamics damping="0.2" friction="0"/>
  </joint>
  <joint name="A_joint_6-tool0" type="fixed">
    <parent link="A_link_6"/>
    <child link="A_tool0"/>
    <origin rpy="0 0 0" xyz="0 0 0"/>
  </joint>
  <!-- end of joint list -->
  <!-- ROS base_link to ABB World Coordinates transform -->
  <link name="A_base"/>
  <joint name="A_base_link-base" type="fixed">
    <origin rpy="0 0 0" xyz="0 0 0"/>
    <parent link="A_base_link"/>
    <child link="A_base"/>
  </joint>
  <joint name="B_world_joint" type="fixed">
    <parent link="world"/>
    <child link="B_axis"/>
    <origin rpy="0.0 0.0 3.14159" xyz="3.70 3.45 0.02"/>
  </joint>
  <!-- Conversion were obtained from http://www.e-paint.co.uk/Lab_values.asp
       unless otherwise stated. -->
  <!-- Conversion were obtained from http://www.e-paint.co.uk/Lab_values.asp
       unless otherwise stated. -->
  <link name="B_axis">
    <inertial>
      <origin xyz="0.0 0.0 0.0"/>
      <mass value="120"/>
      <inertia ixx="-4.98000" ixy="-0.00000" ixz="2.70000" iyy="-5.95200" iyz="-0.00000" izz="0.82800"/>
    </inertial>
    <visual>
      <geometry>
        <mesh filename="package://princeton_cell/meshes/visual/axis.stl"/>
      </geometry>
      <material name="">
        <color rgba="0.9254902 0.9254902 0.9058824 1"/>
      </material>
    </visual>
    <collision>
      <geometry>
        <mesh filename="package://princeton_cell/meshes/collision/axis.stl"/>
      </geometry>
    </collision>
  </link>
  <joint name="B_cart_joint" type="prismatic">
    <parent link="B_axis"/>
    <child link="B_cart"/>
    <origin rpy="0 0 0 " xyz="0 0 0"/>
    <axis xyz="1 0 0"/>
    <limit effort="100000" lower="0.0" upper="4.0" velocity="2.618"/>
    <dynamics damping="0.2" friction="0"/>
  </joint>
  <link name="B_cart">
    <inertial>
      <origin xyz="0.0 0.0 0.0"/>
      <mass value="120.00000"/>
      <inertia ixx="-4.98000" ixy="-0.00000" ixz="2.70000" iyy="-5.95200" iyz="-0.00000" izz="0.82800"/>
    </inertial>
    <visual>
      <geometry>
        <mesh filename="package://princeton_cell/meshes/visual/cart.stl"/>
      </geometry>
      <material name="">
        <color rgba="0.9254902 0.9254902 0.9058824 1"/>
      </material>
    </visual>
    <collision>
      <geometry>
        <mesh filename="package://princeton_cell/meshes/collision/cart.stl"/>
      </geometry>
    </collision>
  </link>
  <joint name="B_abb_joint" type="fixed">
    <parent link="B_cart"/>
    <child link="B_base_link"/>
    <origin rpy="0 0 1.57079632679 " xyz="0 0 0 "/>
    <dynamics damping="0.2" friction="0"/>
  </joint>
  <!-- link list -->
  <link name="B_base_link">
    <inertial>
      <origin xyz="0.0 0.0 0.0"/>
      <mass value="120.00000"/>
      <inertia ixx="-4.98000" ixy="-0.00000" ixz="2.70000" iyy="-5.95200" iyz="-0.00000" izz="0.82800"/>
    </inertial>
    <visual>
      <geometry>
        <mesh filename="package://abb_irb4600_40_255/meshes/visual/base_link.stl"/>
      </geometry>
      <material name="">
        <color rgba="0.7725490 0.7803922 0.7686275 1"/>
      </material>
    </visual>
    <collision>
      <geometry>
        <mesh filename="package://abb_irb4600_40_255/meshes/collision/base_link.stl"/>
      </geometry>
    </collision>
  </link>
  <link name="B_link_1">
    <inertial>
      <origin xyz="0.18000 0.00000 0.50000"/>
      <mass value="120.00000"/>
      <inertia ixx="-4.98000" ixy="-0.00000" ixz="2.70000" iyy="-5.95200" iyz="-0.00000" izz="0.82800"/>
    </inertial>
    <visual>
      <geometry>
        <mesh filename="package://abb_irb4600_40_255/meshes/visual/link_1.stl"/>
      </geometry>
      <material name="">
        <color rgba="0.7725490 0.7803922 0.7686275 1"/>
      </material>
    </visual>
    <collision>
      <geometry>
        <mesh filename="package://abb_irb4600_40_255/meshes/collision/link_1.stl"/>
      </geometry>
    </collision>
  </link>
  <link name="B_link_2">
    <inertial>
      <origin xyz="0.94000 0.08000 -0.34000"/>
      <mass value="120.00000"/>
      <inertia ixx="-2.96000" ixy="2.25600" ixz="-9.58800" iyy="-18.72601" iyz="-0.81600" izz="-14.95000"/>
    </inertial>
    <visual>
      <geometry>
        <mesh filename="package://abb_irb4600_40_255/meshes/visual/link_2.stl"/>
      </geometry>
      <material name="">
        <color rgba="0.7725490 0.7803922 0.7686275 1"/>
      </material>
    </visual>
    <collision>
      <geometry>
        <mesh filename="package://abb_irb4600_40_255/meshes/collision/link_2.stl"/>
      </geometry>
    </collision>
  </link>
  <link name="B_link_3">
    <inertial>
      <origin xyz="0.07000 -0.26600 0.08800"/>
      <mass value="120.00000"/>
      <inertia ixx="1.34500" ixy="-0.55860" ixz="0.18480" iyy="4.65068" iyz="-0.70224" izz="2.76032"/>
    </inertial>
    <visual>
      <geometry>
        <mesh filename="package://abb_irb4600_40_255/meshes/visual/link_3.stl"/>
      </geometry>
      <material name="">
        <color rgba="0.7725490 0.7803922 0.7686275 1"/>
      </material>
    </visual>
    <collision>
      <geometry>
        <mesh filename="package://abb_irb4600_40_255/meshes/collision/link_3.stl"/>
      </geometry>
    </collision>
  </link>
  <link name="B_link_4">
    <inertial>
      <origin xyz="0.00000 0.00000 1.00000"/>
      <mass value="40.00000"/>
      <inertia ixx="-8.00000" ixy="-0.00000" ixz="-0.00000" iyy="-8.00000" iyz="-0.00000" izz="0.48200"/>
    </inertial>
    <visual>
      <geometry>
        <mesh filename="package://abb_irb4600_40_255/meshes/visual/link_4.stl"/>
      </geometry>
      <material name="">
        <color rgba="0.7725490 0.7803922 0.7686275 1"/>
      </material>
    </visual>
    <collision>
      <geometry>
        <mesh filename="package://abb_irb4600_40_255/meshes/collision/link_4.stl"/>
      </geometry>
    </collision>
  </link>
  <link name="B_link_5">
    <inertial>
      <origin xyz="0.14000 0.00000 0.00000"/>
      <mass value="10.00000"/>
      <inertia ixx="0.04000" ixy="-0.00000" ixz="-0.00000" iyy="-0.00900" iyz="-0.00000" izz="-0.00400"/>
    </inertial>
    <visual>
      <geometry>
        <mesh filename="package://abb_irb4600_40_255/meshes/visual/link_5.stl"/>
      </geometry>
      <material name="">
        <color rgba="0.7725490 0.7803922 0.7686275 1"/>
      </material>
    </visual>
    <collision>
      <geometry>
        <mesh filename="package://abb_irb4600_40_255/meshes/collision/link_5.stl"/>
      </geometry>
    </collision>
  </link>
  <link name="B_link_6">
    <inertial>
      <origin xyz="0.08100 -0.09100 0.33200"/>
      <mass value="5.00000"/>
      <inertia ixx="-0.29652" ixy="-0.03686" ixz="0.09396" iyy="-0.28792" iyz="-0.10556" izz="-0.04621"/>
    </inertial>
    <visual>
      <geometry>
        <mesh filename="package://abb_irb4600_40_255/meshes/visual/link_6.stl"/>
      </geometry>
      <material name="">
        <color rgba="0.1882353 0.1960784 0.2039216 1"/>
      </material>
    </visual>
    <collision>
      <geometry>
        <mesh filename="package://abb_irb4600_40_255/meshes/collision/link_6.stl"/>
      </geometry>
    </collision>
  </link>
  <link name="B_tool0"/>
  <!-- end of link list -->
  <!-- joint list -->
  <joint name="B_joint_1" type="revolute">
    <parent link="B_base_link"/>
    <child link="B_link_1"/>
    <origin rpy="0 0 0 " xyz="0 0 0"/>
    <axis xyz="0 0 1"/>
    <limit effort="100000" lower="-3.14159" upper="3.14159" velocity="2.618"/>
    <dynamics damping="0.2" friction="0"/>
  </joint>
  <joint name="B_joint_2" type="revolute">
    <parent link="B_link_1"/>
    <child link="B_link_2"/>
    <origin rpy="0 -0 0 " xyz="0.175 0 0.495"/>
    <axis xyz="0 1 0"/>
    <limit effort="100000" lower="-1.5708" upper="2.61799" velocity="2.618"/>
    <dynamics damping="0.2" friction="0"/>
  </joint>
  <joint name="B_joint_3" type="revolute">
    <parent link="B_link_2"/>
    <child link="B_link_3"/>
    <origin rpy="0 -0 0 " xyz="0 0 1.095"/>
    <axis xyz="0 1 0"/>
    <limit effort="100000" lower="-3.14159" upper="1.309" velocity="2.618"/>
    <dynamics damping="0.2" friction="0"/>
  </joint>
  <joint name="B_joint_4" type="revolute">
    <parent link="B_link_3"/>
    <child link="B_link_4"/>
    <origin rpy="0 -0 0 " xyz="0.332 0 0.175"/>
    <axis xyz="1 0 0"/>
    <limit effort="10000" lower="-6.98132" upper="6.98132" velocity="6.2832"/>
    <dynamics damping="0.2" friction="0"/>
  </joint>
  <joint name="B_joint_5" type="revolute">
    <parent link="B_link_4"/>
    <child link="B_link_5"/>
    <origin rpy="0 -0 0 " xyz="0.939 0 0"/>
    <axis xyz="0 1 0"/>
    <limit effort="100000" lower="-2.18166" upper="2.0944" velocity="6.2832"/>
    <dynamics damping="0.2" friction="0"/>
  </joint>
  <joint name="B_joint_6" type="revolute">
    <parent link="B_link_5"/>
    <child link="B_link_6"/>
    <origin rpy="0 1.57076 0 " xyz="0.135 0 0"/>
    <axis xyz="0 0 1"/>
    <limit effort="100000" lower="-6.98132" upper="6.98132" velocity="7.854"/>
    <dynamics damping="0.2" friction="0"/>
  </joint>
  <joint name="B_joint_6-tool0" type="fixed">
    <parent link="B_link_6"/>
    <child link="B_tool0"/>
    <origin rpy="0 0 0" xyz="0 0 0"/>
  </joint>
  <!-- end of joint list -->
  <!-- ROS base_link to ABB World Coordinates transform -->
  <link name="B_base"/>
  <joint name="B_base_link-base" type="fixed">
    <origin rpy="0 0 0" xyz="0 0 0"/>
    <parent link="B_base_link"/>
    <child link="B_base"/>
  </joint>
</robot>
